ERROR 2020-05-20 15:16:16,697 exception.py [line:132] exception 32099 140509720868608 Internal Server Error: /api/v1/upList/
Traceback (most recent call last):
  File "/usr/lib/python2.7/site-packages/django/core/handlers/exception.py", line 42, in inner
    response = get_response(request)
  File "/usr/lib/python2.7/site-packages/django/core/handlers/base.py", line 187, in _get_response
    response = self.process_exception_by_middleware(e, request)
  File "/usr/lib/python2.7/site-packages/django/core/handlers/base.py", line 185, in _get_response
    response = wrapped_callback(request, *callback_args, **callback_kwargs)
  File "/usr/lib/python2.7/site-packages/django/views/decorators/csrf.py", line 58, in wrapped_view
    return view_func(*args, **kwargs)
  File "/usr/lib/python2.7/site-packages/django/views/generic/base.py", line 68, in view
    return self.dispatch(request, *args, **kwargs)
  File "/usr/lib/python2.7/site-packages/rest_framework/views.py", line 489, in dispatch
    response = self.handle_exception(exc)
  File "/usr/lib/python2.7/site-packages/rest_framework/views.py", line 449, in handle_exception
    self.raise_uncaught_exception(exc)
  File "/usr/lib/python2.7/site-packages/rest_framework/views.py", line 486, in dispatch
    response = handler(request, *args, **kwargs)
  File "/usr/lib/python2.7/site-packages/rest_framework/decorators.py", line 53, in handler
    return func(*args, **kwargs)
  File "/opt/yuantingfei/webapp/jijin/views.py", line 57, in upList
    jijins =  Jijin.objects.filter(Q(name__contains=key)|Q(code__contains=key)).order_by('number')
NameError: global name 'key' is not defined
ERROR 2020-05-20 15:16:24,110 exception.py [line:132] exception 32099 140509720868608 Internal Server Error: /api/v1/upList/
Traceback (most recent call last):
  File "/usr/lib/python2.7/site-packages/django/core/handlers/exception.py", line 42, in inner
    response = get_response(request)
  File "/usr/lib/python2.7/site-packages/django/core/handlers/base.py", line 187, in _get_response
    response = self.process_exception_by_middleware(e, request)
  File "/usr/lib/python2.7/site-packages/django/core/handlers/base.py", line 185, in _get_response
    response = wrapped_callback(request, *callback_args, **callback_kwargs)
  File "/usr/lib/python2.7/site-packages/django/views/decorators/csrf.py", line 58, in wrapped_view
    return view_func(*args, **kwargs)
  File "/usr/lib/python2.7/site-packages/django/views/generic/base.py", line 68, in view
    return self.dispatch(request, *args, **kwargs)
  File "/usr/lib/python2.7/site-packages/rest_framework/views.py", line 489, in dispatch
    response = self.handle_exception(exc)
  File "/usr/lib/python2.7/site-packages/rest_framework/views.py", line 449, in handle_exception
    self.raise_uncaught_exception(exc)
  File "/usr/lib/python2.7/site-packages/rest_framework/views.py", line 486, in dispatch
    response = handler(request, *args, **kwargs)
  File "/usr/lib/python2.7/site-packages/rest_framework/decorators.py", line 53, in handler
    return func(*args, **kwargs)
  File "/opt/yuantingfei/webapp/jijin/views.py", line 57, in upList
    jijins =  Jijin.objects.filter(Q(name__contains=key)|Q(code__contains=key)).order_by('number')
NameError: global name 'key' is not defined
ERROR 2020-05-20 15:18:18,004 exception.py [line:132] exception 403 139840981038848 Internal Server Error: /api/v1/upList/
Traceback (most recent call last):
  File "/usr/lib/python2.7/site-packages/django/core/handlers/exception.py", line 42, in inner
    response = get_response(request)
  File "/usr/lib/python2.7/site-packages/django/core/handlers/base.py", line 187, in _get_response
    response = self.process_exception_by_middleware(e, request)
  File "/usr/lib/python2.7/site-packages/django/core/handlers/base.py", line 185, in _get_response
    response = wrapped_callback(request, *callback_args, **callback_kwargs)
  File "/usr/lib/python2.7/site-packages/django/views/decorators/csrf.py", line 58, in wrapped_view
    return view_func(*args, **kwargs)
  File "/usr/lib/python2.7/site-packages/django/views/generic/base.py", line 68, in view
    return self.dispatch(request, *args, **kwargs)
  File "/usr/lib/python2.7/site-packages/rest_framework/views.py", line 489, in dispatch
    response = self.handle_exception(exc)
  File "/usr/lib/python2.7/site-packages/rest_framework/views.py", line 449, in handle_exception
    self.raise_uncaught_exception(exc)
  File "/usr/lib/python2.7/site-packages/rest_framework/views.py", line 486, in dispatch
    response = handler(request, *args, **kwargs)
  File "/usr/lib/python2.7/site-packages/rest_framework/decorators.py", line 53, in handler
    return func(*args, **kwargs)
  File "/opt/yuantingfei/webapp/jijin/views.py", line 60, in upList
    audit.write_info(request,"jijin","upList:"+id,"tmp_user")
TypeError: cannot concatenate 'str' and 'int' objects
